Workbook

Sheet Sheet2
A3: Row Labels | B3: Count of Total Sales
A4: P101 | B4: 17
A5: P102 | B5: 15
A6: P103 | B6: 16
A7: P104 | B7: 20
A8: P105 | B8: 14
A9: (blank) | B9: 18
A10: Grand Total | B10: 100

Sheet Sheet3
A3: Row Labels | B3: Count of Total Sales
A4: 2024-01-01 | B4: 1
A5: 2024-01-02 | B5: 1
A6: 2024-01-03 | B6: 1
A7: 2024-01-04 | B7: 1
A8: 2024-01-05 | B8: 1
A9: 2024-01-06 | B9: 1
A10: 2024-01-07 | B10: 1
A11: 2024-01-08 | B11: 1
A12: 2024-01-09 | B12: 1
A13: 2024-01-10 | B13: 1
A14: 2024-01-11 | B14: 1
A15: 2024-01-12 | B15: 1
... A104: Grand Total | B104: 100

Sheet Sheet4
A3: Row Labels | B3: Count of Total Sales
A4: Emma | B4: 19
A5: Henry | B5: 20
A6: Joy | B6: 6
A7: Samuel | B7: 55
A8: Grand Total | B8: 100

Sheet Sheet5
A3: Row Labels | B3: Count of Total Sales
A4: 0 | B4: 0.18
A5: Accessories | B5: 0.31
A6: Electronics | B6: 0.51
A7: Grand Total | B7: 1

Sheet Sales_Data
A1: Date | B1: Customer Name | C1: Product ID | D1: Quantity | E1: Sales Rep | F1: Status | G1: Customer Name | H1: Sales Rep | I1: Product Price | J1: Product Category | K1: Sales Rep Department | L1: Monthly Target | M1: Total Sales | N1: Progress
A2: 2024-01-01 | B2: Ali Musa | C2: P102 | D2: 4 | E2: Samuel | F2: pending | G2: =PROPER(TRIM(B2)) -> Ali Musa | H2: =PROPER(TRIM(E2)) -> Samuel | I2: =_xlfn.XLOOKUP(C2,Product_List!$A$2:$A$100,Product_List!$C$2:$C$100) -> 15000 | J2: =_xlfn.XLOOKUP(C2,Product_List!$A$2:$A$100,Product_List!$D$2:$D$100) -> Accessories | K2: =_xlfn.XLOOKUP(E2,Employee_Targets!$A$2:$A$100,Employee_Targets!$B$2:$B$100) -> Retail | L2: =_xlfn.XLOOKUP(E2,Employee_Targets!$A$2:$A$100,Employee_Targets!$C$2:$C$100) -> 500000 | M2: =D2* I2 -> 60000 | N2: =IF(M2>=L2,"Achieved","Not Achieved") -> Not Achieved
A3: 2024-01-02 | B3: AminaBello | C3: P102 | D3: 1 | E3: Joy | F3: pending | G3: =PROPER(TRIM(B3)) -> Aminabello | H3: =PROPER(TRIM(E3)) -> Joy | I3: =_xlfn.XLOOKUP(C3,Product_List!$A$2:$A$100,Product_List!$C$2:$C$100) -> 15000 | J3: =_xlfn.XLOOKUP(C3,Product_List!$A$2:$A$100,Product_List!$D$2:$D$100) -> Accessories | K3: =_xlfn.XLOOKUP(E3,Employee_Targets!$A$2:$A$100,Employee_Targets!$B$2:$B$100) -> Corporate | L3: =_xlfn.XLOOKUP(E3,Employee_Targets!$A$2:$A$100,Employee_Targets!$C$2:$C$100) -> 350000 | M3: =D3* I3 -> 15000 | N3: =IF(M3>=L3,"Achieved","Not Achieved") -> Not Achieved
A4: 2024-01-03 | B4: Uknown Customer | C4: P104 | D4: Average | E4: Samuel | F4: Pending | G4: =PROPER(TRIM(B4)) -> Uknown Customer | H4: =PROPER(TRIM(E4)) -> Samuel | I4: =_xlfn.XLOOKUP(C4,Product_List!$A$2:$A$100,Product_List!$C$2:$C$100) -> 90000 | J4: =_xlfn.XLOOKUP(C4,Product_List!$A$2:$A$100,Product_List!$D$2:$D$100) -> Electronics | K4: =_xlfn.XLOOKUP(E4,Employee_Targets!$A$2:$A$100,Employee_Targets!$B$2:$B$100) -> Retail | L4: =_xlfn.XLOOKUP(E4,Employee_Targets!$A$2:$A$100,Employee_Targets!$C$2:$C$100) -> 500000 | M4: =D4* I4 -> #VALUE! | N4: =IF(M4>=L4,"Achieved","Not Achieved") -> #VALUE!
A5: 2024-01-04 | B5: Ali Musa | C5: P102 | D5: 1 | E5: Henry | F5: pending | G5: =PROPER(TRIM(B5)) -> Ali Musa | H5: =PROPER(TRIM(E5)) -> Henry | I5: =_xlfn.XLOOKUP(C5,Product_List!$A$2:$A$100,Product_List!$C$2:$C$100) -> 15000 | J5: =_xlfn.XLOOKUP(C5,Product_List!$A$2:$A$100,Product_List!$D$2:$D$100) -> Accessories | K5: =_xlfn.XLOOKUP(E5,Employee_Targets!$A$2:$A$100,Employee_Targets!$B$2:$B$100) -> #N/A | L5: =_xlfn.XLOOKUP(E5,Employee_Targets!$A$2:$A$100,Employee_Targets!$C$2:$C$100) -> #N/A | M5: =D5* I5 -> 15000 | N5: =IF(M5>=L5,"Achieved","Not Achieved") -> #N/A
A6: 2024-01-05 | B6: Peter Yusuf | C6: P102 | D6: 1 | E6: Samuel | F6: pending | G6: =PROPER(TRIM(B6)) -> Peter Yusuf | H6: =PROPER(TRIM(E6)) -> Samuel | I6: =_xlfn.XLOOKUP(C6,Product_List!$A$2:$A$100,Product_List!$C$2:$C$100) -> 15000 | J6: =_xlfn.XLOOKUP(C6,Product_List!$A$2:$A$100,Product_List!$D$2:$D$100) -> Accessories | K6: =_xlfn.XLOOKUP(E6,Employee_Targets!$A$2:$A$100,Employee_Targets!$B$2:$B$100) -> Retail | L6: =_xlfn.XLOOKUP(E6,Employee_Targets!$A$2:$A$100,Employee_Targets!$C$2:$C$100) -> 500000 | M6: =D6* I6 -> 15000 | N6: =IF(M6>=L6,"Achieved","Not Achieved") -> Not Achieved
A7: 2024-01-06 | B7: Uknown Customer | C7: P105 | D7: 1 | E7: Samuel | F7: Pending | G7: =PROPER(TRIM(B7)) -> Uknown Customer | H7: =PROPER(TRIM(E7)) -> Samuel | I7: =_xlfn.XLOOKUP(C7,Product_List!$A$2:$A$100,Product_List!$C$2:$C$100) -> 45000 | J7: =_xlfn.XLOOKUP(C7,Product_List!$A$2:$A$100,Product_List!$D$2:$D$100) -> Electronics | K7: =_xlfn.XLOOKUP(E7,Employee_Targets!$A$2:$A$100,Employee_Targets!$B$2:$B$100) -> Retail | L7: =_xlfn.XLOOKUP(E7,Employee_Targets!$A$2:$A$100,Employee_Targets!$C$2:$C$100) -> 500000 | M7: =D7* I7 -> 45000 | N7: =IF(M7>=L7,"Achieved","Not Achieved") -> Not Achieved
A8: 2024-01-07 | B8: Uknown Customer | C8: P104 | D8: 3 | E8: Samuel | F8: pending | G8: =PROPER(TRIM(B8)) -> Uknown Customer | H8: =PROPER(TRIM(E8)) -> Samuel | I8: =_xlfn.XLOOKUP(C8,Product_List!$A$2:$A$100,Product_List!$C$2:$C$100) -> 90000 | J8: =_xlfn.XLOOKUP(C8,Product_List!$A$2:$A$100,Product_List!$D$2:$D$100) -> Electronics | K8: =_xlfn.XLOOKUP(E8,Employee_Targets!$A$2:$A$100,Employee_Targets!$B$2:$B$100) -> Retail | L8: =_xlfn.XLOOKUP(E8,Employee_Targets!$A$2:$A$100,Employee_Targets!$C$2:$C$100) -> 500000 | M8: =D8* I8 -> 270000 | N8: =IF(M8>=L8,"Achieved","Not Achieved") -> Not Achieved
A9: 2024-01-08 | B9: Uknown Customer | C9: P105 | D9: Average | E9: Emma | F9: pending | G9: =PROPER(TRIM(B9)) -> Uknown Customer | H9: =PROPER(TRIM(E9)) -> Emma | I9: =_xlfn.XLOOKUP(C9,Product_List!$A$2:$A$100,Product_List!$C$2:$C$100) -> 45000 | J9: =_xlfn.XLOOKUP(C9,Product_List!$A$2:$A$100,Product_List!$D$2:$D$100) -> Electronics | K9: =_xlfn.XLOOKUP(E9,Employee_Targets!$A$2:$A$100,Employee_Targets!$B$2:$B$100) -> Retail | L9: =_xlfn.XLOOKUP(E9,Employee_Targets!$A$2:$A$100,Employee_Targets!$C$2:$C$100) -> 200000 | M9: =D9* I9 -> #VALUE! | N9: =IF(M9>=L9,"Achieved","Not Achieved") -> #VALUE!
A10: 2024-01-09 | B10: Ali Musa | C10: P105 | D10: 1 | E10: Samuel | F10: pending | G10: =PROPER(TRIM(B10)) -> Ali Musa | H10: =PROPER(TRIM(E10)) -> Samuel | I10: =_xlfn.XLOOKUP(C10,Product_List!$A$2:$A$100,Product_List!$C$2:$C$100) -> 45000 | J10: =_xlfn.XLOOKUP(C10,Product_List!$A$2:$A$100,Product_List!$D$2:$D$100) -> Electronics | K10: =_xlfn.XLOOKUP(E10,Employee_Targets!$A$2:$A$100,Employee_Targets!$B$2:$B$100) -> Retail | L10: =_xlfn.XLOOKUP(E10,Employee_Targets!$A$2:$A$100,Employee_Targets!$C$2:$C$100) -> 500000 | M10: =D10* I10 -> 45000 | N10: =IF(M10>=L10,"Achieved","Not Achieved") -> Not Achieved
A11: 2024-01-10 | B11: Mary Okon | C11: P104 | D11: 4 | E11: Samuel | F11: Delivered | G11: =PROPER(TRIM(B11)) -> Mary Okon | H11: =PROPER(TRIM(E11)) -> Samuel | I11: =_xlfn.XLOOKUP(C11,Product_List!$A$2:$A$100,Product_List!$C$2:$C$100) -> 90000 | J11: =_xlfn.XLOOKUP(C11,Product_List!$A$2:$A$100,Product_List!$D$2:$D$100) -> Electronics | K11: =_xlfn.XLOOKUP(E11,Employee_Targets!$A$2:$A$100,Employee_Targets!$B$2:$B$100) -> Retail | L11: =_xlfn.XLOOKUP(E11,Employee_Targets!$A$2:$A$100,Employee_Targets!$C$2:$C$100) -> 500000 | M11: =D11* I11 -> 360000 | N11: =IF(M11>=L11,"Achieved","Not Achieved") -> Not Achieved
A12: 2024-01-11 | B12: Peter Yusuf | C12: P101 | D12: 5 | E12: Emma | F12: Delivered | G12: =PROPER(TRIM(B12)) -> Peter Yusuf | H12: =PROPER(TRIM(E12)) -> Emma | I12: =_xlfn.XLOOKUP(C12,Product_List!$A$2:$A$100,Product_List!$C$2:$C$100) -> 350000 | J12: =_xlfn.XLOOKUP(C12,Product_List!$A$2:$A$100,Product_List!$D$2:$D$100) -> Electronics | K12: =_xlfn.XLOOKUP(E12,Employee_Targets!$A$2:$A$100,Employee_Targets!$B$2:$B$100) -> Retail | L12: =_xlfn.XLOOKUP(E12,Employee_Targets!$A$2:$A$100,Employee_Targets!$C$2:$C$100) -> 200000 | M12: =D12* I12 -> 1750000 | N12: =IF(M12>=L12,"Achieved","Not Achieved") -> Achieved
A13: 2024-01-12 | B13: Ali Musa | C13: P105 | D13: 1 | E13: Emma | F13: Delivered | G13: =PROPER(TRIM(B13)) -> Ali Musa | H13: =PROPER(TRIM(E13)) -> Emma | I13: =_xlfn.XLOOKUP(C13,Product_List!$A$2:$A$100,Product_List!$C$2:$C$100) -> 45000 | J13: =_xlfn.XLOOKUP(C13,Product_List!$A$2:$A$100,Product_List!$D$2:$D$100) -> Electronics | K13: =_xlfn.XLOOKUP(E13,Employee_Targets!$A$2:$A$100,Employee_Targets!$B$2:$B$100) -> Retail | L13: =_xlfn.XLOOKUP(E13,Employee_Targets!$A$2:$A$100,Employee_Targets!$C$2:$C$100) -> 200000 | M13: =D13* I13 -> 45000 | N13: =IF(M13>=L13,"Achieved","Not Achieved") -> Not Achieved
A14: 2024-01-13 | B14: Peter Yusuf | D14: 3 | E14: Emma | F14: Pending | G14: =PROPER(TRIM(B14)) -> Peter Yusuf | H14: =PROPER(TRIM(E14)) -> Emma | I14: =_xlfn.XLOOKUP(C14,Product_List!$A$2:$A$100,Product_List!$C$2:$C$100) -> 0 | J14: =_xlfn.XLOOKUP(C14,Product_List!$A$2:$A$100,Product_List!$D$2:$D$100) -> 0 | K14: =_xlfn.XLOOKUP(E14,Employee_Targets!$A$2:$A$100,Employee_Targets!$B$2:$B$100) -> Retail | L14: =_xlfn.XLOOKUP(E14,Employee_Targets!$A$2:$A$100,Employee_Targets!$C$2:$C$100) -> 200000 | M14: =D14* I14 -> 0 | N14: =IF(M14>=L14,"Achieved","Not Achieved") -> Not Achieved
A15: 2024-01-14 | B15: Peter Yusuf | D15: Average | E15: Samuel | F15: Returned | G15: =PROPER(TRIM(B15)) -> Peter Yusuf | H15: =PROPER(TRIM(E15)) -> Samuel | I15: =_xlfn.XLOOKUP(C15,Product_List!$A$2:$A$100,Product_List!$C$2:$C$100) -> 0 | J15: =_xlfn.XLOOKUP(C15,Product_List!$A$2:$A$100,Product_List!$D$2:$D$100) -> 0 | K15: =_xlfn.XLOOKUP(E15,Employee_Targets!$A$2:$A$100,Employee_Targets!$B$2:$B$100) -> Retail | L15: =_xlfn.XLOOKUP(E15,Employee_Targets!$A$2:$A$100,Employee_Targets!$C$2:$C$100) -> 500000 | M15: =D15* I15 -> #VALUE! | N15: =IF(M15>=L15,"Achieved","Not Achieved") -> #VALUE!
A16: 2024-01-15 | B16: Uknown Customer | C16: P102 | D16: 3 | E16: Henry | F16: pending | G16: =PROPER(TRIM(B16)) -> Uknown Customer | H16: =PROPER(TRIM(E16)) -> Henry | I16: =_xlfn.XLOOKUP(C16,Product_List!$A$2:$A$100,Product_List!$C$2:$C$100) -> 15000 | J16: =_xlfn.XLOOKUP(C16,Product_List!$A$2:$A$100,Product_List!$D$2:$D$100) -> Accessories | K16: =_xlfn.XLOOKUP(E16,Employee_Targets!$A$2:$A$100,Employee_Targets!$B$2:$B$100) -> #N/A | L16: =_xlfn.XLOOKUP(E16,Employee_Targets!$A$2:$A$100,Employee_Targets!$C$2:$C$100) -> #N/A | M16: =D16* I16 -> 45000 | N16: =IF(M16>=L16,"Achieved","Not Achieved") -> #N/A
A17: 2024-01-16 | B17: Uknown Customer | D17: 1 | E17: Samuel | F17: pending | G17: =PROPER(TRIM(B17)) -> Uknown Customer | H17: =PROPER(TRIM(E17)) -> Samuel | I17: =_xlfn.XLOOKUP(C17,Product_List!$A$2:$A$100,Product_List!$C$2:$C$100) -> 0 | J17: =_xlfn.XLOOKUP(C17,Product_List!$A$2:$A$100,Product_List!$D$2:$D$100) -> 0 | K17: =_xlfn.XLOOKUP(E17,Employee_Targets!$A$2:$A$100,Employee_Targets!$B$2:$B$100) -> Retail | L17: =_xlfn.XLOOKUP(E17,Employee_Targets!$A$2:$A$100,Employee_Targets!$C$2:$C$100) -> 500000 | M17: =D17* I17 -> 0 | N17: =IF(M17>=L17,"Achieved","Not Achieved") -> Not Achieved
A18: 2024-01-17 | B18: Amina Bello | C18: P102 | D18: Average | E18: Samuel | F18: Pending | G18: =PROPER(TRIM(B18)) -> Amina Bello | H18: =PROPER(TRIM(E18)) -> Samuel | I18: =_xlfn.XLOOKUP(C18,Product_List!$A$2:$A$100,Product_List!$C$2:$C$100) -> 15000 | J18: =_xlfn.XLOOKUP(C18,Product_List!$A$2:$A$100,Product_List!$D$2:$D$100) -> Accessories | K18: =_xlfn.XLOOKUP(E18,Employee_Targets!$A$2:$A$100,Employee_Targets!$B$2:$B$100) -> Retail | L18: =_xlfn.XLOOKUP(E18,Employee_Targets!$A$2:$A$100,Employee_Targets!$C$2:$C$100) -> 500000 | M18: =D18* I18 -> #VALUE! | N18: =IF(M18>=L18,"Achieved","Not Achieved") -> #VALUE!
A19: 2024-01-18 | B19: Uknown Customer | C19: P101 | D19: 5 | E19: Emma | F19: pending | G19: =PROPER(TRIM(B19)) -> Uknown Customer | H19: =PROPER(TRIM(E19)) -> Emma | I19: =_xlfn.XLOOKUP(C19,Product_List!$A$2:$A$100,Product_List!$C$2:$C$100) -> 350000 | J19: =_xlfn.XLOOKUP(C19,Product_List!$A$2:$A$100,Product_List!$D$2:$D$100) -> Electronics | K19: =_xlfn.XLOOKUP(E19,Employee_Targets!$A$2:$A$100,Employee_Targets!$B$2:$B$100) -> Retail | L19: =_xlfn.XLOOKUP(E19,Employee_Targets!$A$2:$A$100,Employee_Targets!$C$2:$C$100) -> 200000 | M19: =D19* I19 -> 1750000 | N19: =IF(M19>=L19,"Achieved","Not Achieved") -> Achieved
A20: 2024-01-19 | B20: Uknown Customer | C20: P104 | D20: 1 | E20: Samuel | F20: Delivered | G20: =PROPER(TRIM(B20)) -> Uknown Customer | H20: =PROPER(TRIM(E20)) -> Samuel | I20: =_xlfn.XLOOKUP(C20,Product_List!$A$2:$A$100,Product_List!$C$2:$C$100) -> 90000 | J20: =_xlfn.XLOOKUP(C20,Product_List!$A$2:$A$100,Product_List!$D$2:$D$100) -> Electronics | K20: =_xlfn.XLOOKUP(E20,Employee_Targets!$A$2:$A$100,Employee_Targets!$B$2:$B$100) -> Retail | L20: =_xlfn.XLOOKUP(E20,Employee_Targets!$A$2:$A$100,Employee_Targets!$C$2:$C$100) -> 500000 | M20: =D20* I20 -> 90000 | N20: =IF(M20>=L20,"Achieved","Not Achieved") -> Not Achieved
A21: 2024-01-20 | B21: Peter Yusuf | C21: P104 | D21: 3 | E21: Samuel | F21: Returned | G21: =PROPER(TRIM(B21)) -> Peter Yusuf | H21: =PROPER(TRIM(E21)) -> Samuel | I21: =_xlfn.XLOOKUP(C21,Product_List!$A$2:$A$100,Product_List!$C$2:$C$100) -> 90000 | J21: =_xlfn.XLOOKUP(C21,Product_List!$A$2:$A$100,Product_List!$D$2:$D$100) -> Electronics | K21: =_xlfn.XLOOKUP(E21,Employee_Targets!$A$2:$A$100,Employee_Targets!$B$2:$B$100) -> Retail | L21: =_xlfn.XLOOKUP(E21,Employee_Targets!$A$2:$A$100,Employee_Targets!$C$2:$C$100) -> 500000 | M21: =D21* I21 -> 270000 | N21: =IF(M21>=L21,"Achieved","Not Achieved") -> Not Achieved
A22: 2024-01-21 | B22: Grace | C22: P104 | D22: 2 | E22: Henry | F22: pending | G22: =PROPER(TRIM(B22)) -> Grace | H22: =PROPER(TRIM(E22)) -> Henry | I22: =_xlfn.XLOOKUP(C22,Product_List!$A$2:$A$100,Product_List!$C$2:$C$100) -> 90000 | J22: =_xlfn.XLOOKUP(C22,Product_List!$A$2:$A$100,Product_List!$D$2:$D$100) -> Electronics | K22: =_xlfn.XLOOKUP(E22,Employee_Targets!$A$2:$A$100,Employee_Targets!$B$2:$B$100) -> #N/A | L22: =_xlfn.XLOOKUP(E22,Employee_Targets!$A$2:$A$100,Employee_Targets!$C$2:$C$100) -> #N/A | M22: =D22* I22 -> 180000 | N22: =IF(M22>=L22,"Achieved","Not Achieved") -> #N/A
A23: 2024-01-22 | B23: Uknown Customer | D23: 4 | E23: Samuel | F23: pending | G23: =PROPER(TRIM(B23)) -> Uknown Customer | H23: =PROPER(TRIM(E23)) -> Samuel | I23: =_xlfn.XLOOKUP(C23,Product_List!$A$2:$A$100,Product_List!$C$2:$C$100) -> 0 | J23: =_xlfn.XLOOKUP(C23,Product_List!$A$2:$A$100,Product_List!$D$2:$D$100) -> 0 | K23: =_xlfn.XLOOKUP(E23,Employee_Targets!$A$2:$A$100,Employee_Targets!$B$2:$B$100) -> Retail | L23: =_xlfn.XLOOKUP(E23,Employee_Targets!$A$2:$A$100,Employee_Targets!$C$2:$C$100) -> 500000 | M23: =D23* I23 -> 0 | N23: =IF(M23>=L23,"Achieved","Not Achieved") -> Not Achieved
A24: 2024-01-23 | B24: Mary Okon | C24: P101 | D24: 3 | E24: Henry | F24: Delivered | G24: =PROPER(TRIM(B24)) -> Mary Okon | H24: =PROPER(TRIM(E24)) -> Henry | I24: =_xlfn.XLOOKUP(C24,Product_List!$A$2:$A$100,Product_List!$C$2:$C$100) -> 350000 | J24: =_xlfn.XLOOKUP(C24,Product_List!$A$2:$A$100,Product_List!$D$2:$D$100) -> Electronics | K24: =_xlfn.XLOOKUP(E24,Employee_Targets!$A$2:$A$100,Employee_Targets!$B$2:$B$100) -> #N/A | L24: =_xlfn.XLOOKUP(E24,Employee_Targets!$A$2:$A$100,Employee_Targets!$C$2:$C$100) -> #N/A | M24: =D24* I24 -> 1050000 | N24: =IF(M24>=L24,"Achieved","Not Achieved") -> #N/A
A25: 2024-01-24 | B25: Uknown Customer | D25: Average | E25: Emma | F25: pending | G25: =PROPER(TRIM(B25)) -> Uknown Customer | H25: =PROPER(TRIM(E25)) -> Emma | I25: =_xlfn.XLOOKUP(C25,Product_List!$A$2:$A$100,Product_List!$C$2:$C$100) -> 0 | J25: =_xlfn.XLOOKUP(C25,Product_List!$A$2:$A$100,Product_List!$D$2:$D$100) -> 0 | K25: =_xlfn.XLOOKUP(E25,Employee_Targets!$A$2:$A$100,Employee_Targets!$B$2:$B$100) -> Retail | L25: =_xlfn.XLOOKUP(E25,Employee_Targets!$A$2:$A$100,Employee_Targets!$C$2:$C$100) -> 200000 | M25: =D25* I25 -> #VALUE! | N25: =IF(M25>=L25,"Achieved","Not Achieved") -> #VALUE!
A26: 2024-01-25 | B26: Amina Bello | D26: 1 | E26: Henry | F26: Returned | G26: =PROPER(TRIM(B26)) -> Amina Bello | H26: =PROPER(TRIM(E26)) -> Henry | I26: =_xlfn.XLOOKUP(C26,Product_List!$A$2:$A$100,Product_List!$C$2:$C$100) -> 0 | J26: =_xlfn.XLOOKUP(C26,Product_List!$A$2:$A$100,Product_List!$D$2:$D$100) -> 0 | K26: =_xlfn.XLOOKUP(E26,Employee_Targets!$A$2:$A$100,Employee_Targets!$B$2:$B$100) -> #N/A | L26: =_xlfn.XLOOKUP(E26,Employee_Targets!$A$2:$A$100,Employee_Targets!$C$2:$C$100) -> #N/A | M26: =D26* I26 -> 0 | N26: =IF(M26>=L26,"Achieved","Not Achieved") -> #N/A
A27: 2024-01-26 | B27: Grace | C27: P101 | D27: 4 | E27: Samuel | F27: pending | G27: =PROPER(TRIM(B27)) -> Grace | H27: =PROPER(TRIM(E27)) -> Samuel | I27: =_xlfn.XLOOKUP(C27,Product_List!$A$2:$A$100,Product_List!$C$2:$C$100) -> 350000 | J27: =_xlfn.XLOOKUP(C27,Product_List!$A$2:$A$100,Product_List!$D$2:$D$100) -> Electronics | K27: =_xlfn.XLOOKUP(E27,Employee_Targets!$A$2:$A$100,Employee_Targets!$B$2:$B$100) -> Retail | L27: =_xlfn.XLOOKUP(E27,Employee_Targets!$A$2:$A$100,Employee_Targets!$C$2:$C$100) -> 500000 | M27: =D27* I27 -> 1400000 | N27: =IF(M27>=L27,"Achieved","Not Achieved") -> Achieved
A28: 2024-01-27 | B28: Grace | C28: P101 | D28: 1 | E28: Emma | F28: Delivered | G28: =PROPER(TRIM(B28)) -> Grace | H28: =PROPER(TRIM(E28)) -> Emma | I28: =_xlfn.XLOOKUP(C28,Product_List!$A$2:$A$100,Product_List!$C$2:$C$100) -> 350000 | J28: =_xlfn.XLOOKUP(C28,Product_List!$A$2:$A$100,Product_List!$D$2:$D$100) -> Electronics | K28: =_xlfn.XLOOKUP(E28,Employee_Targets!$A$2:$A$100,Employee_Targets!$B$2:$B$100) -> Retail | L28: =_xlfn.XLOOKUP(E28,Employee_Targets!$A$2:$A$100,Employee_Targets!$C$2:$C$100) -> 200000 | M28: =D28* I28 -> 350000 | N28: =IF(M28>=L28,"Achieved","Not Achieved") -> Achieved
A29: 2024-01-28 | B29: Mary Okon | C29: P101 | D29: Average | E29: Samuel | F29: pending | G29: =PROPER(TRIM(B29)) -> Mary Okon | H29: =PROPER(TRIM(E29)) -> Samuel | I29: =_xlfn.XLOOKUP(C29,Product_List!$A$2:$A$100,Product_List!$C$2:$C$100) -> 350000 | J29: =_xlfn.XLOOKUP(C29,Product_List!$A$2:$A$100,Product_List!$D$2:$D$100) -> Electronics | K29: =_xlfn.XLOOKUP(E29,Employee_Targets!$A$2:$A$100,Employee_Targets!$B$2:$B$100) -> Retail | L29: =_xlfn.XLOOKUP(E29,Employee_Targets!$A$2:$A$100,Employee_Targets!$C$2:$C$100) -> 500000 | M29: =D29* I29 -> #VALUE! | N29: =IF(M29>=L29,"Achieved","Not Achieved") -> #VALUE!
A30: 2024-01-29 | B30: Uknown Customer | C30: P101 | D30: 1 | E30: Samuel | F30: Pending | G30: =PROPER(TRIM(B30)) -> Uknown Customer | H30: =PROPER(TRIM(E30)) -> Samuel | I30: =_xlfn.XLOOKUP(C30,Product_List!$A$2:$A$100,Product_List!$C$2:$C$100) -> 350000 | J30: =_xlfn.XLOOKUP(C30,Product_List!$A$2:$A$100,Product_List!$D$2:$D$100) -> Electronics | K30: =_xlfn.XLOOKUP(E30,Employee_Targets!$A$2:$A$100,Employee_Targets!$B$2:$B$100) -> Retail | L30: =_xlfn.XLOOKUP(E30,Employee_Targets!$A$2:$A$100,Employee_Targets!$C$2:$C$100) -> 500000 | M30: =D30* I30 -> 350000 | N30: =IF(M30>=L30,"Achieved","Not Achieved") -> Not Achieved
A31: 2024-01-30 | B31: Amina Bello | C31: P104 | D31: 2 | E31: Joy | F31: pending | G31: =PROPER(TRIM(B31)) -> Amina Bello | H31: =PROPER(TRIM(E31)) -> Joy | I31: =_xlfn.XLOOKUP(C31,Product_List!$A$2:$A$100,Product_List!$C$2:$C$100) -> 90000 | J31: =_xlfn.XLOOKUP(C31,Product_List!$A$2:$A$100,Product_List!$D$2:$D$100) -> Electronics | K31: =_xlfn.XLOOKUP(E31,Employee_Targets!$A$2:$A$100,Employee_Targets!$B$2:$B$100) -> Corporate | L31: =_xlfn.XLOOKUP(E31,Employee_Targets!$A$2:$A$100,Employee_Targets!$C$2:$C$100) -> 350000 | M31: =D31* I31 -> 180000 | N31: =IF(M31>=L31,"Achieved","Not Achieved") -> Not Achieved
A32: 2024-01-31 | B32: Uknown Customer | C32: P103 | D32: 4 | E32: Henry | F32: pending | G32: =PROPER(TRIM(B32)) -> Uknown Customer | H32: =PROPER(TRIM(E32)) -> Henry | I32: =_xlfn.XLOOKUP(C32,Product_List!$A$2:$A$100,Product_List!$C$2:$C$100) -> 5000 | J32: =_xlfn.XLOOKUP(C32,Product_List!$A$2:$A$100,Product_List!$D$2:$D$100) -> Accessories | K32: =_xlfn.XLOOKUP(E32,Employee_Targets!$A$2:$A$100,Employee_Targets!$B$2:$B$100) -> #N/A | L32: =_xlfn.XLOOKUP(E32,Employee_Targets!$A$2:$A$100,Employee_Targets!$C$2:$C$100) -> #N/A | M32: =D32* I32 -> 20000 | N32: =IF(M32>=L32,"Achieved","Not Achieved") -> #N/A
A33: 2024-02-01 | B33: John Ade | C33: P103 | D33: 4 | E33: Joy | F33: pending | G33: =PROPER(TRIM(B33)) -> John Ade | H33: =PROPER(TRIM(E33)) -> Joy | I33: =_xlfn.XLOOKUP(C33,Product_List!$A$2:$A$100,Product_List!$C$2:$C$100) -> 5000 | J33: =_xlfn.XLOOKUP(C33,Product_List!$A$2:$A$100,Product_List!$D$2:$D$100) -> Accessories | K33: =_xlfn.XLOOKUP(E33,Employee_Targets!$A$2:$A$100,Employee_Targets!$B$2:$B$100) -> Corporate | L33: =_xlfn.XLOOKUP(E33,Employee_Targets!$A$2:$A$100,Employee_Targets!$C$2:$C$100) -> 350000 | M33: =D33* I33 -> 20000 | N33: =IF(M33>=L33,"Achieved","Not Achieved") -> Not Achieved
A34: 2024-02-02 | B34: Amina Bello | C34: P101 | D34: Average | E34: Joy | F34: Pending | G34: =PROPER(TRIM(B34)) -> Amina Bello | H34: =PROPER(TRIM(E34)) -> Joy | I34: =_xlfn.XLOOKUP(C34,Product_List!$A$2:$A$100,Product_List!$C$2:$C$100) -> 350000 | J34: =_xlfn.XLOOKUP(C34,Product_List!$A$2:$A$100,Product_List!$D$2:$D$100) -> Electronics | K34: =_xlfn.XLOOKUP(E34,Employee_Targets!$A$2:$A$100,Employee_Targets!$B$2:$B$100) -> Corporate | L34: =_xlfn.XLOOKUP(E34,Employee_Targets!$A$2:$A$100,Employee_Targets!$C$2:$C$100) -> 350000 | M34: =D34* I34 -> #VALUE! | N34: =IF(M34>=L34,"Achieved","Not Achieved") -> #VALUE!
A35: 2024-02-03 | B35: Mary Okon | C35: P103 | D35: 2 | E35: Henry | F35: Delivered | G35: =PROPER(TRIM(B35)) -> Mary Okon | H35: =PROPER(TRIM(E35)) -> Henry | I35: =_xlfn.XLOOKUP(C35,Product_List!$A$2:$A$100,Product_List!$C$2:$C$100) -> 5000 | J35: =_xlfn.XLOOKUP(C35,Product_List!$A$2:$A$100,Product_List!$D$2:$D$100) -> Accessories | K35: =_xlfn.XLOOKUP(E35,Employee_Targets!$A$2:$A$100,Employee_Targets!$B$2:$B$100) -> #N/A | L35: =_xlfn.XLOOKUP(E35,Employee_Targets!$A$2:$A$100,Employee_Targets!$C$2:$C$100) -> #N/A | M35: =D35* I35 -> 10000 | N35: =IF(M35>=L35,"Achieved","Not Achieved") -> #N/A
A36: 2024-02-04 | B36: Grace | C36: P103 | D36: 3 | E36: Emma | F36: pending | G36: =PROPER(TRIM(B36)) -> Grace | H36: =PROPER(TRIM(E36)) -> Emma | I36: =_xlfn.XLOOKUP(C36,Product_List!$A$2:$A$100,Product_List!$C$2:$C$100) -> 5000 | J36: =_xlfn.XLOOKUP(C36,Product_List!$A$2:$A$100,Product_List!$D$2:$D$100) -> Accessories | K36: =_xlfn.XLOOKUP(E36,Employee_Targets!$A$2:$A$100,Employee_Targets!$B$2:$B$100) -> Retail | L36: =_xlfn.XLOOKUP(E36,Employee_Targets!$A$2:$A$100,Employee_Targets!$C$2:$C$100) -> 200000 | M36: =D36* I36 -> 15000 | N36: =IF(M36>=L36,"Achieved","Not Achieved") -> Not Achieved
A37: 2024-02-05 | B37: Uknown Customer | C37: P101 | D37: 1 | E37: Samuel | F37: Returned | G37: =PROPER(TRIM(B37)) -> Uknown Customer | H37: =PROPER(TRIM(E37)) -> Samuel | I37: =_xlfn.XLOOKUP(C37,Product_List!$A$2:$A$100,Product_List!$C$2:$C$100) -> 350000 | J37: =_xlfn.XLOOKUP(C37,Product_List!$A$2:$A$100,Product_List!$D$2:$D$100) -> Electronics | K37: =_xlfn.XLOOKUP(E37,Employee_Targets!$A$2:$A$100,Employee_Targets!$B$2:$B$100) -> Retail | L37: =_xlfn.XLOOKUP(E37,Employee_Targets!$A$2:$A$100,Employee_Targets!$C$2:$C$100) -> 500000 | M37: =D37* I37 -> 350000 | N37: =IF(M37>=L37,"Achieved","Not Achieved") -> Not Achieved
A38: 2024-02-06 | B38: Amina Bello | C38: P103 | D38: 5 | E38: Samuel | F38: pending | G38: =PROPER(TRIM(B38)) -> Amina Bello | H38: =PROPER(TRIM(E38)) -> Samuel | I38: =_xlfn.XLOOKUP(C38,Product_List!$A$2:$A$100,Product_List!$C$2:$C$100) -> 5000 | J38: =_xlfn.XLOOKUP(C38,Product_List!$A$2:$A$100,Product_List!$D$2:$D$100) -> Accessories | K38: =_xlfn.XLOOKUP(E38,Employee_Targets!$A$2:$A$100,Employee_Targets!$B$2:$B$100) -> Retail | L38: =_xlfn.XLOOKUP(E38,Employee_Targets!$A$2:$A$100,Employee_Targets!$C$2:$C$100) -> 500000 | M38: =D38* I38 -> 25000 | N38: =IF(M38>=L38,"Achieved","Not Achieved") -> Not Achieved
A39: 2024-02-07 | B39: John Ade | D39: 1 | E39: Samuel | F39: pending | G39: =PROPER(TRIM(B39)) -> John Ade | H39: =PROPER(TRIM(E39)) -> Samuel | I39: =_xlfn.XLOOKUP(C39,Product_List!$A$2:$A$100,Product_List!$C$2:$C$100) -> 0 | J39: =_xlfn.XLOOKUP(C39,Product_List!$A$2:$A$100,Product_List!$D$2:$D$100) -> 0 | K39: =_xlfn.XLOOKUP(E39,Employee_Targets!$A$2:$A$100,Employee_Targets!$B$2:$B$100) -> Retail | L39: =_xlfn.XLOOKUP(E39,Employee_Targets!$A$2:$A$100,Employee_Targets!$C$2:$C$100) -> 500000 | M39: =D39* I39 -> 0 | N39: =IF(M39>=L39,"Achieved","Not Achieved") -> Not Achieved
A40: 2024-02-08 | B40: John Ade | C40: P102 | D40: 1 | E40: Samuel | F40: Delivered | G40: =PROPER(TRIM(B40)) -> John Ade | H40: =PROPER(TRIM(E40)) -> Samuel | I40: =_xlfn.XLOOKUP(C40,Product_List!$A$2:$A$100,Product_List!$C$2:$C$100) -> 15000 | J40: =_xlfn.XLOOKUP(C40,Product_List!$A$2:$A$100,Product_List!$D$2:$D$100) -> Accessories | K40: =_xlfn.XLOOKUP(E40,Employee_Targets!$A$2:$A$100,Employee_Targets!$B$2:$B$100) -> Retail | L40: =_xlfn.XLOOKUP(E40,Employee_Targets!$A$2:$A$100,Employee_Targets!$C$2:$C$100) -> 500000 | M40: =D40* I40 -> 15000 | N40: =IF(M40>=L40,"Achieved","Not Achieved") -> Not Achieved
...

Sheet Product_List
A1: Product ID | B1: Product Name | C1: Price | D1: Category
A2: P101 | B2: Laptop | C2: 350000 | D2: Electronics
A3: P102 | B3: Keyboard | C3: 15000 | D3: Accessories
A4: P103 | B4: Mouse | C4: 5000 | D4: Accessories
A5: P104 | B5: Monitor | C5: 90000 | D5: Electronics
A6: P105 | B6: Printer | C6: 45000 | D6: Electronics

Sheet Employee_Targets
A1: Sales Rep | B1: Department | C1: Monthly Target
A2: Samuel | B2: Retail | C2: 500000
A3: Joy | B3: Corporate | C3: 350000
A4: Emma | B4: Retail | C4: 200000
A5: Henry | B5: Online | C5: 150000
